Workbook

Sheet INICIO
A1: CONGRESO NACIONAL DE DETALLADORES 2026
A2: Libro Maestro de Operaciones · Versión 2.0 · Tablero de control
A3: 30, 31 de julio y 1 de agosto de 2026 · Responsable General: Gerardo Rodríguez Miranda
A4: "La excelencia es el resultado de una preparación extraordinaria."
A5: AVANCE POR FASE
A6: Fase | B6: Inventario | C6: Tareas | D6: Avance global | E6: Semáforo | F6: Ir a
A7: ① ANTES | B7: =COUNTIF('INVENTARIO MAESTRO'!E4:H108,TRUE)/(COUNTA('INVENTARIO MAESTRO'!B4:B108)*4) -> 0.23333333 | C7: =IFERROR(COUNTIF(ANTES!F6:F27,"Hecho")/COUNT(ANTES!A6:A27),0) -> 0.058823529 | D7: =AVERAGE(B7:C7) -> 0.14607843 | E7: =IF(D7>=0.9,"● LISTO",IF(D7>=0.5,"● EN CURSO","● PENDIENTE")) -> ● PENDIENTE | F7: Abrir →
A8: ② DURANTE | B8: =COUNTIF('INVENTARIO MAESTRO'!I4:J108,TRUE)/(COUNTA('INVENTARIO MAESTRO'!B4:B108)*2) -> 0 | C8: =IFERROR(COUNTIF(DURANTE!F6:F27,"Hecho")/COUNT(DURANTE!A6:A27),0) -> 0 | D8: =AVERAGE(B8:C8) -> 0 | E8: =IF(D8>=0.9,"● LISTO",IF(D8>=0.5,"● EN CURSO","● PENDIENTE")) -> ● PENDIENTE | F8: Abrir →
A9: ③ DESPUÉS | B9: =COUNTIF('INVENTARIO MAESTRO'!K4:K108,TRUE)/COUNTA('INVENTARIO MAESTRO'!B4:B108) -> 0 | C9: =IFERROR(COUNTIF(DESPUÉS!F6:F19,"Hecho")/COUNT(DESPUÉS!A6:A19),0) -> 0 | D9: =AVERAGE(B9:C9) -> 0 | E9: =IF(D9>=0.9,"● LISTO",IF(D9>=0.5,"● EN CURSO","● PENDIENTE")) -> ● PENDIENTE | F9: Abrir →
A10: TOTAL | B10: =AVERAGE(B7:B9) -> 0.077777778 | C10: =AVERAGE(C7:C9) -> 0.019607843 | D10: =AVERAGE(D7:D9) -> 0.04869281 | E10: =IF(D10>=0.9,"● LISTO",IF(D10>=0.5,"● EN CURSO","● PENDIENTE")) -> ● PENDIENTE

Sheet INVENTARIO MAESTRO
A1: INVENTARIO MAESTRO DE EQUIPO · CNDD 2026
A2: DATOS DEL EQUIPO | E2: ① | I2: ② | K2: ③ | L2: SEGUIMIENTO
A3: Categoría | B3: Material | C3: Cantidad | D3: Responsable | E3: Conseguido | F3: Probado | G3: Empacado | H3: Cargado | I3: Instalado | J3: Revisado | K3: Regresó | L3: Avance ① | M3: Avance ② | N3: Avance ③ | O3: Observaciones
A4: Audio y Video | B4: Micrófonos | C4: 5 | D4: =IFERROR(_xlfn.XLOOKUP($A4,'DIRECTORIO Y PENDIENTES'!$A$4:$A$17,'DIRECTORIO Y PENDIENTES'!$B$4:$B$17,""),"") -> Luis Gerardo Rodríguez | E4: TRUE | F4: TRUE | G4: TRUE | H4: FALSE | I4: FALSE | J4: FALSE | K4: FALSE | L4: =COUNTIF(E4:H4,TRUE)/4 -> 0.75 | M4: =COUNTIF(I4:J4,TRUE)/2 -> 0 | N4: =COUNTIF(K4,TRUE)/1 -> 0 | O4: 1 microfono no funciona, no se mando arreglar
A5: Audio y Video | B5: Bocinas | C5: 1 | D5: =IFERROR(_xlfn.XLOOKUP($A5,'DIRECTORIO Y PENDIENTES'!$A$4:$A$17,'DIRECTORIO Y PENDIENTES'!$B$4:$B$17,""),"") -> Luis Gerardo Rodríguez | E5: TRUE | F5: TRUE | G5: TRUE | H5: FALSE | I5: FALSE | J5: FALSE | K5: FALSE | L5: =COUNTIF(E5:H5,TRUE)/4 -> 0.75 | M5: =COUNTIF(I5:J5,TRUE)/2 -> 0 | N5: =COUNTIF(K5,TRUE)/1 -> 0
A6: Audio y Video | B6: Laptop | C6: 1 | D6: =IFERROR(_xlfn.XLOOKUP($A6,'DIRECTORIO Y PENDIENTES'!$A$4:$A$17,'DIRECTORIO Y PENDIENTES'!$B$4:$B$17,""),"") -> Luis Gerardo Rodríguez | E6: TRUE | F6: TRUE | G6: FALSE | H6: FALSE | I6: FALSE | J6: FALSE | K6: FALSE | L6: =COUNTIF(E6:H6,TRUE)/4 -> 0.5 | M6: =COUNTIF(I6:J6,TRUE)/2 -> 0 | N6: =COUNTIF(K6,TRUE)/1 -> 0
A7: Audio y Video | B7: Adaptadores | C7: 2 | D7: =IFERROR(_xlfn.XLOOKUP($A7,'DIRECTORIO Y PENDIENTES'!$A$4:$A$17,'DIRECTORIO Y PENDIENTES'!$B$4:$B$17,""),"") -> Luis Gerardo Rodríguez | E7: TRUE | F7: TRUE | G7: FALSE | H7: FALSE | I7: FALSE | J7: FALSE | K7: FALSE | L7: =COUNTIF(E7:H7,TRUE)/4 -> 0.5 | M7: =COUNTIF(I7:J7,TRUE)/2 -> 0 | N7: =COUNTIF(K7,TRUE)/1 -> 0
A8: Audio y Video | B8: HDMI | C8: 1 | D8: =IFERROR(_xlfn.XLOOKUP($A8,'DIRECTORIO Y PENDIENTES'!$A$4:$A$17,'DIRECTORIO Y PENDIENTES'!$B$4:$B$17,""),"") -> Luis Gerardo Rodríguez | E8: TRUE | F8: TRUE | G8: FALSE | H8: FALSE | I8: FALSE | J8: FALSE | K8: FALSE | L8: =COUNTIF(E8:H8,TRUE)/4 -> 0.5 | M8: =COUNTIF(I8:J8,TRUE)/2 -> 0 | N8: =COUNTIF(K8,TRUE)/1 -> 0
A9: Audio y Video | B9: USB | C9: 1 | D9: =IFERROR(_xlfn.XLOOKUP($A9,'DIRECTORIO Y PENDIENTES'!$A$4:$A$17,'DIRECTORIO Y PENDIENTES'!$B$4:$B$17,""),"") -> Luis Gerardo Rodríguez | E9: TRUE | F9: TRUE | G9: FALSE | H9: FALSE | I9: FALSE | J9: FALSE | K9: FALSE | L9: =COUNTIF(E9:H9,TRUE)/4 -> 0.5 | M9: =COUNTIF(I9:J9,TRUE)/2 -> 0 | N9: =COUNTIF(K9,TRUE)/1 -> 0
A10: Audio y Video | B10: Proyector | C10: 1 | D10: =IFERROR(_xlfn.XLOOKUP($A10,'DIRECTORIO Y PENDIENTES'!$A$4:$A$17,'DIRECTORIO Y PENDIENTES'!$B$4:$B$17,""),"") -> Luis Gerardo Rodríguez | E10: TRUE | F10: TRUE | G10: TRUE | H10: FALSE | I10: FALSE | J10: FALSE | K10: FALSE | L10: =COUNTIF(E10:H10,TRUE)/4 -> 0.75 | M10: =COUNTIF(I10:J10,TRUE)/2 -> 0 | N10: =COUNTIF(K10,TRUE)/1 -> 0
A11: Audio y Video | B11: Ventilador para laptop | C11: 1 | D11: =IFERROR(_xlfn.XLOOKUP($A11,'DIRECTORIO Y PENDIENTES'!$A$4:$A$17,'DIRECTORIO Y PENDIENTES'!$B$4:$B$17,""),"") -> Luis Gerardo Rodríguez | E11: TRUE | F11: TRUE | G11: FALSE | H11: FALSE | I11: FALSE | J11: FALSE | K11: FALSE | L11: =COUNTIF(E11:H11,TRUE)/4 -> 0.5 | M11: =COUNTIF(I11:J11,TRUE)/2 -> 0 | N11: =COUNTIF(K11,TRUE)/1 -> 0
A12: Coffee Break | B12: Refrescos | D12: =IFERROR(_xlfn.XLOOKUP($A12,'DIRECTORIO Y PENDIENTES'!$A$4:$A$17,'DIRECTORIO Y PENDIENTES'!$B$4:$B$17,""),"") -> Jully Rodriguez | E12: FALSE | F12: FALSE | G12: FALSE | H12: FALSE | I12: FALSE | J12: FALSE | K12: FALSE | L12: =COUNTIF(E12:H12,TRUE)/4 -> 0 | M12: =COUNTIF(I12:J12,TRUE)/2 -> 0 | N12: =COUNTIF(K12,TRUE)/1 -> 0
A13: Coffee Break | B13: Agua | D13: =IFERROR(_xlfn.XLOOKUP($A13,'DIRECTORIO Y PENDIENTES'!$A$4:$A$17,'DIRECTORIO Y PENDIENTES'!$B$4:$B$17,""),"") -> Jully Rodriguez | E13: FALSE | F13: FALSE | G13: FALSE | H13: FALSE | I13: FALSE | J13: FALSE | K13: FALSE | L13: =COUNTIF(E13:H13,TRUE)/4 -> 0 | M13: =COUNTIF(I13:J13,TRUE)/2 -> 0 | N13: =COUNTIF(K13,TRUE)/1 -> 0
A14: Coffee Break | B14: Hielo | D14: =IFERROR(_xlfn.XLOOKUP($A14,'DIRECTORIO Y PENDIENTES'!$A$4:$A$17,'DIRECTORIO Y PENDIENTES'!$B$4:$B$17,""),"") -> Jully Rodriguez | E14: FALSE | F14: FALSE | G14: FALSE | H14: FALSE | I14: FALSE | J14: FALSE | K14: FALSE | L14: =COUNTIF(E14:H14,TRUE)/4 -> 0 | M14: =COUNTIF(I14:J14,TRUE)/2 -> 0 | N14: =COUNTIF(K14,TRUE)/1 -> 0
A15: Coffee Break | B15: Hielera | D15: =IFERROR(_xlfn.XLOOKUP($A15,'DIRECTORIO Y PENDIENTES'!$A$4:$A$17,'DIRECTORIO Y PENDIENTES'!$B$4:$B$17,""),"") -> Jully Rodriguez | E15: FALSE | F15: FALSE | G15: FALSE | H15: FALSE | I15: FALSE | J15: FALSE | K15: FALSE | L15: =COUNTIF(E15:H15,TRUE)/4 -> 0 | M15: =COUNTIF(I15:J15,TRUE)/2 -> 0 | N15: =COUNTIF(K15,TRUE)/1 -> 0
A16: Coffee Break | B16: Botanas | D16: =IFERROR(_xlfn.XLOOKUP($A16,'DIRECTORIO Y PENDIENTES'!$A$4:$A$17,'DIRECTORIO Y PENDIENTES'!$B$4:$B$17,""),"") -> Jully Rodriguez | E16: FALSE | F16: FALSE | G16: FALSE | H16: FALSE | I16: FALSE | J16: FALSE | K16: FALSE | L16: =COUNTIF(E16:H16,TRUE)/4 -> 0 | M16: =COUNTIF(I16:J16,TRUE)/2 -> 0 | N16: =COUNTIF(K16,TRUE)/1 -> 0
A17: Coffee Break | B17: Salsas | D17: =IFERROR(_xlfn.XLOOKUP($A17,'DIRECTORIO Y PENDIENTES'!$A$4:$A$17,'DIRECTORIO Y PENDIENTES'!$B$4:$B$17,""),"") -> Jully Rodriguez | E17: FALSE | F17: FALSE | G17: FALSE | H17: FALSE | I17: FALSE | J17: FALSE | K17: FALSE | L17: =COUNTIF(E17:H17,TRUE)/4 -> 0 | M17: =COUNTIF(I17:J17,TRUE)/2 -> 0 | N17: =COUNTIF(K17,TRUE)/1 -> 0
A18: Coffee Break | B18: Cafetera | D18: =IFERROR(_xlfn.XLOOKUP($A18,'DIRECTORIO Y PENDIENTES'!$A$4:$A$17,'DIRECTORIO Y PENDIENTES'!$B$4:$B$17,""),"") -> Jully Rodriguez | E18: FALSE | F18: FALSE | G18: FALSE | H18: FALSE | I18: FALSE | J18: FALSE | K18: FALSE | L18: =COUNTIF(E18:H18,TRUE)/4 -> 0 | M18: =COUNTIF(I18:J18,TRUE)/2 -> 0 | N18: =COUNTIF(K18,TRUE)/1 -> 0
A19: Coffee Break | B19: Café | D19: =IFERROR(_xlfn.XLOOKUP($A19,'DIRECTORIO Y PENDIENTES'!$A$4:$A$17,'DIRECTORIO Y PENDIENTES'!$B$4:$B$17,""),"") -> Jully Rodriguez | E19: FALSE | F19: FALSE | G19: FALSE | H19: FALSE | I19: FALSE | J19: FALSE | K19: FALSE | L19: =COUNTIF(E19:H19,TRUE)/4 -> 0 | M19: =COUNTIF(I19:J19,TRUE)/2 -> 0 | N19: =COUNTIF(K19,TRUE)/1 -> 0
A20: Coffee Break | B20: Té | D20: =IFERROR(_xlfn.XLOOKUP($A20,'DIRECTORIO Y PENDIENTES'!$A$4:$A$17,'DIRECTORIO Y PENDIENTES'!$B$4:$B$17,""),"") -> Jully Rodriguez | E20: FALSE | F20: FALSE | G20: FALSE | H20: FALSE | I20: FALSE | J20: FALSE | K20: FALSE | L20: =COUNTIF(E20:H20,TRUE)/4 -> 0 | M20: =COUNTIF(I20:J20,TRUE)/2 -> 0 | N20: =COUNTIF(K20,TRUE)/1 -> 0
A21: Coffee Break | B21: Azúcar | D21: =IFERROR(_xlfn.XLOOKUP($A21,'DIRECTORIO Y PENDIENTES'!$A$4:$A$17,'DIRECTORIO Y PENDIENTES'!$B$4:$B$17,""),"") -> Jully Rodriguez | E21: FALSE | F21: FALSE | G21: FALSE | H21: FALSE | I21: FALSE | J21: FALSE | K21: FALSE | L21: =COUNTIF(E21:H21,TRUE)/4 -> 0 | M21: =COUNTIF(I21:J21,TRUE)/2 -> 0 | N21: =COUNTIF(K21,TRUE)/1 -> 0
A22: Coffee Break | B22: Vasos | D22: =IFERROR(_xlfn.XLOOKUP($A22,'DIRECTORIO Y PENDIENTES'!$A$4:$A$17,'DIRECTORIO Y PENDIENTES'!$B$4:$B$17,""),"") -> Jully Rodriguez | E22: FALSE | F22: FALSE | G22: FALSE | H22: FALSE | I22: FALSE | J22: FALSE | K22: FALSE | L22: =COUNTIF(E22:H22,TRUE)/4 -> 0 | M22: =COUNTIF(I22:J22,TRUE)/2 -> 0 | N22: =COUNTIF(K22,TRUE)/1 -> 0
A23: Coffee Break | B23: Vasos unicel | D23: =IFERROR(_xlfn.XLOOKUP($A23,'DIRECTORIO Y PENDIENTES'!$A$4:$A$17,'DIRECTORIO Y PENDIENTES'!$B$4:$B$17,""),"") -> Jully Rodriguez | E23: FALSE | F23: FALSE | G23: FALSE | H23: FALSE | I23: FALSE | J23: FALSE | K23: FALSE | L23: =COUNTIF(E23:H23,TRUE)/4 -> 0 | M23: =COUNTIF(I23:J23,TRUE)/2 -> 0 | N23: =COUNTIF(K23,TRUE)/1 -> 0
... A28: Coffee Break | B28: Bolsas de basura | D28: =IFERROR(_xlfn.XLOOKUP($A28,'DIRECTORIO Y PENDIENTES'!$A$4:$A$17,'DIRECTORIO Y PENDIENTES'!$B$4:$B$17,""),"") -> Jully Rodriguez | E28: FALSE | F28: FALSE | G28: FALSE | H28: FALSE | I28: FALSE | J28: FALSE | K28: FALSE | L28: =COUNTIF(E28:H28,TRUE)/4 -> 0 | M28: =COUNTIF(I28:J28,TRUE)/2 -> 0 | N28: =COUNTIF(K28,TRUE)/1 -> 0
A29: Comunicación | B29: Puntero láser de presentación | C29: 1 | D29: =IFERROR(_xlfn.XLOOKUP($A29,'DIRECTORIO Y PENDIENTES'!$A$4:$A$17,'DIRECTORIO Y PENDIENTES'!$B$4:$B$17,""),"") -> Luis Gerardo Rodríguez | E29: TRUE | F29: TRUE | G29: FALSE | H29: FALSE | I29: FALSE | J29: FALSE | K29: FALSE | L29: =COUNTIF(E29:H29,TRUE)/4 -> 0.5 | M29: =COUNTIF(I29:J29,TRUE)/2 -> 0 | N29: =COUNTIF(K29,TRUE)/1 -> 0
A30: Comunicación | B30: Radios de comunicación | C30: 6 | D30: =IFERROR(_xlfn.XLOOKUP($A30,'DIRECTORIO Y PENDIENTES'!$A$4:$A$17,'DIRECTORIO Y PENDIENTES'!$B$4:$B$17,""),"") -> Luis Gerardo Rodríguez | E30: TRUE | F30: TRUE | G30: FALSE | H30: FALSE | I30: FALSE | J30: FALSE | K30: FALSE | L30: =COUNTIF(E30:H30,TRUE)/4 -> 0.5 | M30: =COUNTIF(I30:J30,TRUE)/2 -> 0 | N30: =COUNTIF(K30,TRUE)/1 -> 0
A31: Comunicación | B31: Baterías AAA | C31: 24 | D31: =IFERROR(_xlfn.XLOOKUP($A31,'DIRECTORIO Y PENDIENTES'!$A$4:$A$17,'DIRECTORIO Y PENDIENTES'!$B$4:$B$17,""),"") -> Luis Gerardo Rodríguez | E31: TRUE | F31: TRUE | G31: FALSE | H31: FALSE | I31: FALSE | J31: FALSE | K31: FALSE | L31: =COUNTIF(E31:H31,TRUE)/4 -> 0.5 | M31: =COUNTIF(I31:J31,TRUE)/2 -> 0 | N31: =COUNTIF(K31,TRUE)/1 -> 0 | O31: Necesitamos 24 en total
A32: Comunicación | B32: Baterías AA | C32: 8 | D32: =IFERROR(_xlfn.XLOOKUP($A32,'DIRECTORIO Y PENDIENTES'!$A$4:$A$17,'DIRECTORIO Y PENDIENTES'!$B$4:$B$17,""),"") -> Luis Gerardo Rodríguez | E32: TRUE | F32: TRUE | G32: FALSE | H32: FALSE | I32: FALSE | J32: FALSE | K32: FALSE | L32: =COUNTIF(E32:H32,TRUE)/4 -> 0.5 | M32: =COUNTIF(I32:J32,TRUE)/2 -> 0 | N32: =COUNTIF(K32,TRUE)/1 -> 0 | O32: Necesitamos 12 en total
A33: Comunicación | B33: Cargadores de baterías | C33: 2 | D33: =IFERROR(_xlfn.XLOOKUP($A33,'DIRECTORIO Y PENDIENTES'!$A$4:$A$17,'DIRECTORIO Y PENDIENTES'!$B$4:$B$17,""),"") -> Luis Gerardo Rodríguez | E33: TRUE | F33: TRUE | G33: FALSE | H33: FALSE | I33: FALSE | J33: FALSE | K33: FALSE | L33: =COUNTIF(E33:H33,TRUE)/4 -> 0.5 | M33: =COUNTIF(I33:J33,TRUE)/2 -> 0 | N33: =COUNTIF(K33,TRUE)/1 -> 0
A34: Comunicación | B34: Lista de asignación radios | C34: 1 | D34: =IFERROR(_xlfn.XLOOKUP($A34,'DIRECTORIO Y PENDIENTES'!$A$4:$A$17,'DIRECTORIO Y PENDIENTES'!$B$4:$B$17,""),"") -> Luis Gerardo Rodríguez | E34: TRUE | F34: FALSE | G34: FALSE | H34: FALSE | I34: FALSE | J34: FALSE | K34: FALSE | L34: =COUNTIF(E34:H34,TRUE)/4 -> 0.25 | M34: =COUNTIF(I34:J34,TRUE)/2 -> 0 | N34: =COUNTIF(K34,TRUE)/1 -> 0
A35: Dinámicas | B35: Material jueves | D35: =IFERROR(_xlfn.XLOOKUP($A35,'DIRECTORIO Y PENDIENTES'!$A$4:$A$17,'DIRECTORIO Y PENDIENTES'!$B$4:$B$17,""),"") -> Gerardo Rodríguez Miranda | E35: FALSE | F35: FALSE | G35: FALSE | H35: FALSE | I35: FALSE | J35: FALSE | K35: FALSE | L35: =COUNTIF(E35:H35,TRUE)/4 -> 0 | M35: =COUNTIF(I35:J35,TRUE)/2 -> 0 | N35: =COUNTIF(K35,TRUE)/1 -> 0
A36: Dinámicas | B36: Material viernes | D36: =IFERROR(_xlfn.XLOOKUP($A36,'DIRECTORIO Y PENDIENTES'!$A$4:$A$17,'DIRECTORIO Y PENDIENTES'!$B$4:$B$17,""),"") -> Gerardo Rodríguez Miranda | E36: FALSE | F36: FALSE | G36: FALSE | H36: FALSE | I36: FALSE | J36: FALSE | K36: FALSE | L36: =COUNTIF(E36:H36,TRUE)/4 -> 0 | M36: =COUNTIF(I36:J36,TRUE)/2 -> 0 | N36: =COUNTIF(K36,TRUE)/1 -> 0
A37: Dinámicas | B37: Visita autolavado | D37: =IFERROR(_xlfn.XLOOKUP($A37,'DIRECTORIO Y PENDIENTES'!$A$4:$A$17,'DIRECTORIO Y PENDIENTES'!$B$4:$B$17,""),"") -> Gerardo Rodríguez Miranda | E37: FALSE | F37: FALSE | G37: FALSE | H37: FALSE | I37: FALSE | J37: FALSE | K37: FALSE | L37: =COUNTIF(E37:H37,TRUE)/4 -> 0 | M37: =COUNTIF(I37:J37,TRUE)/2 -> 0 | N37: =COUNTIF(K37,TRUE)/1 -> 0
A38: Emergencias | B38: Botiquín | D38: =IFERROR(_xlfn.XLOOKUP($A38,'DIRECTORIO Y PENDIENTES'!$A$4:$A$17,'DIRECTORIO Y PENDIENTES'!$B$4:$B$17,""),"") -> Yatziri Rodriguez | E38: FALSE | F38: FALSE | G38: FALSE | H38: FALSE | I38: FALSE | J38: FALSE | K38: FALSE | L38: =COUNTIF(E38:H38,TRUE)/4 -> 0 | M38: =COUNTIF(I38:J38,TRUE)/2 -> 0 | N38: =COUNTIF(K38,TRUE)/1 -> 0
A39: Emergencias | B39: Extensiones extra | D39: =IFERROR(_xlfn.XLOOKUP($A39,'DIRECTORIO Y PENDIENTES'!$A$4:$A$17,'DIRECTORIO Y PENDIENTES'!$B$4:$B$17,""),"") -> Yatziri Rodriguez | E39: FALSE | F39: FALSE | G39: FALSE | H39: FALSE | I39: FALSE | J39: FALSE | K39: FALSE | L39: =COUNTIF(E39:H39,TRUE)/4 -> 0 | M39: =COUNTIF(I39:J39,TRUE)/2 -> 0 | N39: =COUNTIF(K39,TRUE)/1 -> 0
A40: Emergencias | B40: Multicontactos extra | D40: =IFERROR(_xlfn.XLOOKUP($A40,'DIRECTORIO Y PENDIENTES'!$A$4:$A$17,'DIRECTORIO Y PENDIENTES'!$B$4:$B$17,""),"") -> Yatziri Rodriguez | E40: FALSE | F40: FALSE | G40: FALSE | H40: FALSE | I40: FALSE | J40: FALSE | K40: FALSE | L40: =COUNTIF(E40:H40,TRUE)/4 -> 0 | M40: =COUNTIF(I40:J40,TRUE)/2 -> 0 | N40: =COUNTIF(K40,TRUE)/1 -> 0
A41: Emergencias | B41: Herramientas | D41: =IFERROR(_xlfn.XLOOKUP($A41,'DIRECTORIO Y PENDIENTES'!$A$4:$A$17,'DIRECTORIO Y PENDIENTES'!$B$4:$B$17,""),"") -> Yatziri Rodriguez | E41: FALSE | F41: FALSE | G41: FALSE | H41: FALSE | I41: FALSE | J41: FALSE | K41: FALSE | L41: =COUNTIF(E41:H41,TRUE)/4 -> 0 | M41: =COUNTIF(I41:J41,TRUE)/2 -> 0 | N41: =COUNTIF(K41,TRUE)/1 -> 0
A42: Energía y Herramientas | B42: Extensiones | D42: =IFERROR(_xlfn.XLOOKUP($A42,'DIRECTORIO Y PENDIENTES'!$A$4:$A$17,'DIRECTORIO Y PENDIENTES'!$B$4:$B$17,""),"") -> Luis Gerardo Rodríguez | E42: FALSE | F42: FALSE | G42: FALSE | H42: FALSE | I42: FALSE | J42: FALSE | K42: FALSE | L42: =COUNTIF(E42:H42,TRUE)/4 -> 0 | M42: =COUNTIF(I42:J42,TRUE)/2 -> 0 | N42: =COUNTIF(K42,TRUE)/1 -> 0
A43: Energía y Herramientas | B43: Multicontactos | D43: =IFERROR(_xlfn.XLOOKUP($A43,'DIRECTORIO Y PENDIENTES'!$A$4:$A$17,'DIRECTORIO Y PENDIENTES'!$B$4:$B$17,""),"") -> Luis Gerardo Rodríguez | E43: FALSE | F43: FALSE | G43: FALSE | H43: FALSE | I43: FALSE | J43: FALSE | K43: FALSE | L43: =COUNTIF(E43:H43,TRUE)/4 -> 0 | M43: =COUNTIF(I43:J43,TRUE)/2 -> 0 | N43: =COUNTIF(K43,TRUE)/1 -> 0
A44: Energía y Herramientas | B44: Reguladores | D44: =IFERROR(_xlfn.XLOOKUP($A44,'DIRECTORIO Y PENDIENTES'!$A$4:$A$17,'DIRECTORIO Y PENDIENTES'!$B$4:$B$17,""),"") -> Luis Gerardo Rodríguez | E44: FALSE | F44: FALSE | G44: FALSE | H44: FALSE | I44: FALSE | J44: FALSE | K44: FALSE | L44: =COUNTIF(E44:H44,TRUE)/4 -> 0 | M44: =COUNTIF(I44:J44,TRUE)/2 -> 0 | N44: =COUNTIF(K44,TRUE)/1 -> 0
...

Sheet ANTES
A1: ① ANTES DEL CONGRESO
A2: Preparación · días previos (hasta el 29 de julio)
A3: Avance de esta fase: | C3: =IFERROR(COUNTIF(F6:F27,"Hecho")/COUNT(A6:A27),0) -> 0.058823529
A5: # | B5: Bloque / Momento | C5: Tarea | D5: Responsable | E5: Fecha límite | F5: Estado
A6: LOGÍSTICA Y SEDE
A7: 1 | B7: Sede | C7: Confirmar reservación y salones — Hotel Racquet Cuernavaca | D7: Gerardo Rodríguez Miranda | E7: 46232 | F7: Pendiente
A8: 2 | B8: Sede | C8: Confirmar cantidades de coffee break y alimentos según # de asistentes | D8: Gerardo Rodríguez Miranda | E8: 46232 | F8: Pendiente
A9: 3 | B9: Sede | C9: Confirmar visita a autolavado (Dinámicas) | D9: Gerardo Rodríguez Miranda | E9: 46232 | F9: Pendiente
A10: EQUIPO Y MATERIAL
A11: 4 | B11: Equipo | C11: Probar TODO el equipo de detallado (pulidoras, compresora, tornador) | D11: Alfredo Rodriguez | E11: 46232 | F11: Pendiente
A12: 5 | B12: Equipo | C12: Cargar baterías de radios y power banks | D12: Luis Gerardo Rodríguez | E12: 46232 | F12: Hecho
A13: 6 | B13: Equipo | C13: Empacar y cargar material a vehículos (ver Inventario Maestro) | D13: Luis Gerardo Rodríguez | E13: 46232 | F13: Pendiente
A14: 7 | B14: Equipo | C14: Verificar combustible y llaves de vehículos | D14: Gerardo Rodríguez Miranda | E14: 46232 | F14: Pendiente
A15: 8 | B15: Equipo | C15: Armar kit de emergencias (botiquín, extensiones/multicontactos extra) | D15: Yatziri Rodriguez | E15: 46232 | F15: Pendiente
A16: REGISTRO E IMAGEN
A17: 9 | B17: Registro | C17: Imprimir credenciales, gafetes y pasaporte técnico | D17: Mirna Solis | E17: 46232 | F17: Pendiente
A18: 10 | B18: Registro | C18: Cerrar lista de asistentes definitiva | D18: Gerardo Rodríguez Miranda | E18: 46232 | F18: Pendiente
A19: 11 | B19: Imagen | C19: Diseñar y mandar imprimir lonas, back CNDD, photocall y señalización | D19: Pavel Sanchez | E19: 46232 | F19: Pendiente
A20: PATROCINADORES Y CONTENIDO
A21: 12 | B21: Patroc. | C21: Confirmar asistencia y necesidades de los 14 patrocinadores | D21: Gerardo Rodríguez Miranda | E21: 46232 | F21: Pendiente
A22: 13 | B22: IDA | C22: Preparar exámenes y material de certificación IDA | D22: Marco Rivas | E22: 46232 | F22: Pendiente
A23: 14 | B23: A/V | C23: Probar audio, micrófonos, laptop y cargar presentaciones | D23: Luis Gerardo Rodríguez | E23: 46232 | F23: Pendiente
A24: 15 | B24: Dinámicas | C24: Preparar material de dinámicas de jueves y viernes | D24: Gerardo Rodríguez Miranda | E24: 46232 | F24: Pendiente
A25: STAFF
A26: 16 | B26: Staff | C26: Entregar camisas, gorras y termos al staff | D26: Alfredo Rodriguez | E26: 46232 | F26: Pendiente
A27: 17 | B27: Staff | C27: Reunión final de staff y confirmar roles asignados | D27: Gerardo Rodríguez Miranda | E27: 46232 | F27: Pendiente

Sheet DURANTE
A1: ② DURANTE EL CONGRESO
A2: Ejecución · 30, 31 jul y 1 ago 2026 · Hotel Racquet Cuernavaca
A3: Avance de esta fase: | C3: =IFERROR(COUNTIF(F6:F27,"Hecho")/COUNT(A6:A27),0) -> 0
A5: # | B5: Bloque / Momento | C5: Tarea | D5: Responsable | E5: Fecha límite | F5: Estado
A6: JUEVES 30 DE JULIO
A7: 1 | B7: Jue 30 | C7: Montaje de sede: imagen, señalización y photocall | E7: 46233 | F7: Pendiente
A8: 2 | B8: Jue 30 | C8: Instalación de audio y video + prueba de sonido | D8: Luis Gerardo Rodríguez | E8: 46233 | F8: Pendiente
A9: 3 | B9: Jue 30 | C9: Montaje de mesas y sillas (IDA) | E9: 46233 | F9: Pendiente
A10: 4 | B10: Jue 30 | C10: Apertura de registro y entrega de gafetes | D10: Mirna Solis | E10: 46233 | F10: Pendiente
A11: 5 | B11: Jue 30 | C11: Coffee break montado y operando | D11: Jully Rodriguez | E11: 46233 | F11: Pendiente
A12: 6 | B12: Jue 30 | C12: Dinámica de jueves | E12: 46233 | F12: Pendiente
A13: VIERNES 31 DE JULIO
A14: 7 | B14: Vie 31 | C14: Registro de rezagados | E14: 46233 | F14: Pendiente
A15: 8 | B15: Vie 31 | C15: Sesiones técnicas y demostraciones de patrocinadores | D15: Gerardo Rodríguez Miranda | E15: 46233 | F15: Pendiente
A16: 9 | B16: Vie 31 | C16: Reposición de consumibles (microfibras, pads, diluciones) | E16: 46233 | F16: Pendiente
A17: 10 | B17: Vie 31 | C17: Coffee break | D17: Jully Rodriguez | E17: 46233 | F17: Pendiente
A18: 11 | B18: Vie 31 | C18: Dinámica de viernes | E18: 46233 | F18: Pendiente
A19: SÁBADO 1 DE AGOSTO
A20: 12 | B20: Sáb 1 | C20: Aplicación de exámenes IDA | D20: Marco Rivas | E20: 46233 | F20: Pendiente
A21: 13 | B21: Sáb 1 | C21: Sesión de cierre | E21: 46233 | F21: Pendiente
A22: 14 | B22: Sáb 1 | C22: Fotografía grupal en photocall | E22: 46233 | F22: Pendiente
A23: 15 | B23: Sáb 1 | C23: Reconocimientos / premiaciones | D23: Gerardo Rodríguez Miranda | E23: 46233 | F23: Pendiente
A24: OPERACIÓN CONTINUA (los 3 días)
A25: 16 | B25: Continuo | C25: Radios operativos y coordinación por área | D25: Luis Gerardo Rodríguez | E25: 46233 | F25: Pendiente
A26: 17 | B26: Continuo | C26: Monitoreo de emergencias y botiquín accesible | D26: Yatziri Rodriguez | E26: 46233 | F26: Pendiente
A27: 19 | B27: Continuo | C27: Control de inventario en piso (Instalado/Revisado) | D27: Luis Gerardo Rodríguez | E27: 46233 | F27: Pendiente

Sheet DESPUÉS
A1: ③ DESPUÉS DEL CONGRESO
A2: Cierre y seguimiento · a partir del 2 de agosto
A3: Avance de esta fase: | C3: =IFERROR(COUNTIF(F6:F19,"Hecho")/COUNT(A6:A19),0) -> 0
A5: # | B5: Bloque / Momento | C5: Tarea | D5: Responsable | E5: Fecha límite | F5: Estado
A6: CIERRE OPERATIVO
A7: 1 | B7: Cierre | C7: Desmontaje | D7: Pavel Sanchez | E7: 46235 | F7: Pendiente
A8: 2 | B8: Cierre | C8: Regreso y conteo de TODO el equipo (marcar 'Regresó' en Inventario) | D8: Luis Gerardo Rodríguez | E8: 46235 | F8: Pendiente
A9: 3 | B9: Cierre | C9: Revisar daños o faltantes de equipo | D9: Luis Gerardo Rodríguez | E9: 46235 | F9: Pendiente
A10: 4 | B10: Cierre | C10: Devolver equipo rentado | D10: Luis Gerardo Rodríguez | E10: 46235 | F10: Pendiente
A11: SEGUIMIENTO
A12: 5 | B12: Segui. | C12: Reporte de resultados de exámenes IDA | D12: Marco Rivas | E12: 46235 | F12: Pendiente
A13: 6 | B13: Segui. | C13: Agradecimiento formal a los 14 patrocinadores | D13: Gerardo Rodríguez Miranda | E13: 46235 | F13: Pendiente
A14: 7 | B14: Segui. | C14: Enviar encuesta de satisfacción a asistentes | D14: Gerardo Rodríguez Miranda | E14: 46235 | F14: Pendiente
A15: 8 | B15: Segui. | C15: Respaldo de fotos y video del evento | E15: 46235 | F15: Pendiente
A16: BALANCE
A17: 9 | B17: Balance | C17: Corte de caja: gastos reales vs presupuesto | D17: Mirna Solis | E17: 46235 | F17: Pendiente
A18: 10 | B18: Balance | C18: Reunión de retroalimentación con staff | D18: Gerardo Rodríguez Miranda | E18: 46235 | F18: Pendiente
A19: 11 | B19: Balance | C19: Reporte final del congreso (aprendizajes y mejoras) | D19: Gerardo Rodríguez Miranda | E19: 46235 | F19: Pendiente

Sheet DIRECTORIO Y PENDIENTES
A1: DIRECTORIO DE RESPONSABLES
A2: Área | B2: Responsable | C2: Notas
A3: Responsable General | B3: Gerardo Rodríguez Miranda
A4: Equipo de Detallado | B4: Alfredo Rodriguez
A5: Medición e Inspección | B5: Alfredo Rodriguez
A6: Energía y Herramientas | B6: Luis Gerardo Rodríguez
A7: Comunicación | B7: Luis Gerardo Rodríguez
A8: Registro | B8: Mirna Solis
A9: Staff | B9: Mirna Solis
A10: Audio y Video | B10: Luis Gerardo Rodríguez
A11: Imagen del Evento | B11: Pavel Sanchez
A12: Coffee Break | B12: Jully Rodriguez
A13: IDA | B13: Marco Rivas
A14: Patrocinadores | B14: Gerardo Rodríguez Miranda
... A17: Emergencias | B17: Yatziri Rodriguez
A19: PENDIENTES DE ÚLTIMO MOMENTO
A20: # | B20: Pendiente | C20: Estado
A21: 1 | B21: Microfonos | C21: Hecho
A22: 2 | B22: Baterías para microfonos | C22: Pendiente
A23: 3 | B23: Microfonos para celular | C23: Pendiente
A24: 4 | B24: Estabilizador para celular | C24: Pendiente
A25: 5 | C25: Pendiente
A26: 6 | C26: Pendiente
A27: 7 | C27: Pendiente
A28: 8 | C28: Pendiente
A29: 9 | C29: Pendiente
A30: 10 | C30: Pendiente
A31: 11 | C31: Pendiente
A32: 12 | C32: Pendiente
A33: 13 | C33: Pendiente
A34: 14 | C34: Pendiente
A35: 15 | C35: Pendiente

Sheet LISTA DE ASIGNACIÓN
A1: LISTA DE ASIGNACIÓN DE EQUIPO · CNDD 2026
A2: N.º / Equipo | B2: Responsable | C2: Área / Rol | D2: Hora de entrega | E2: Hora de devolución
A3: RADIO 1
A4: RADIO 2
A5: RADIO 3
A6: RADIO 4
A7: RADIO 5
A8: RADIO 6
